Workbook

Sheet Group Members
C2: S.No | D2: ID | E2: Name | F2: Company Assigned
C3: 1 | D3: 2022A3PS1224P | E3: Vishwam Aggarwal | F3: Anupam Rasayan Ltd.
C4: 2 | D4: 2022A1PS1356P | E4: Anand Kashyap
C5: 3 | D5: 2022A1PS1075P | E5: Ayush Saharia
C6: 4 | D6: 2022A1PS0883P | E6: Samagra Kumar Tiwari

Sheet CAPM (Monthly) (Part-1)
A1: Data for Anupam Rasayan | D1: Returns | F1: DATA for NIFTY 50 | H1: Return | O1: Market Returns for NIFTY 50 | S1: Average Market Return | T1: 91 day T-bill | X1: Market Risk Premium | AA1: Dividend Data | AM1: Liability Breakdown (Rs in Millions) | AP1: Interest Expense (Rs in Millions) | AS1: Bond Yield Plus Risk Premium Approach (Cost of Equity=Bond Yield+ Equity Risk Premium) | BE1: The Fama-French Three-Factor Model Formula:
A2: Date | B2: Close | F2: Date | G2: Close | J2: Covariance | K2: Variance | L2: Beta | O2: 2024 | T2: (Risk free Rate) | X2: (Rm-RFR) | AA2: Announcement Date | AB2: Ex-Dividend Date | AC2: Dividend (Rs) | AE2: Years | AF2: Sum of Dividend (Rs) | AH2: We can clearly see that dividend given out by the company is showing a clear negative trend hence dividend discount model of any kind cannot be used. | AM2: Total Liability | AN2: 16143.58 | AP2: Interest Expense | AQ2: 792.69 | BM2: All values are in % | BQ2: MF (market Factor/ Market Return): | BR2: RF (Risk Free Rate):
A3: 44256 | B3: 489.15 | F3: 44256 | G3: 14690.7 | J3: =_xlfn.COVARIANCE.P(D4:D47,H4:H47) -> 0.0017156319 | K3: =_xlfn.VAR.P(H4:H47) -> 0.0013534673 | L3: =J3/K3 -> 1.2675828 | O3: 2023 | P3: 19.42 | S3: 15.609167 | T3: 6.5 | U3: Cost of Equity (CAPM) = | V3: =V4*100 -> 18.046623 | W3: % | X3: =(S4-T4) -> 0.091091667 | AA3: 45433 | AB3: 45552 | AC3: 0.75 | AE3: 2021 | AF3: 3 | AM3: Current Liability | AN3: 12663.46 | AP3: Other Borrowing Cost | AQ3: 44.48 | BK3: Date:- | BL3: Excess Return on Asset | BM3: SMB | BN3: HML | BO3: Rm-Rf | BP3: WML
A4: 44287 | B4: 624.25 | D4: =(B4-B3)/B3 -> 0.2761934 | F4: 44287 | G4: 14631.1 | H4: =(G4-G3)/G3 -> -0.0040569884 | O4: 2022 | P4: 4.32 | S4: =S3/100 -> 0.15609167 | T4: =T3/100 -> 0.065 | V4: =T4+L3*(S4-T4) -> 0.18046623 | X4: =X3*100 -> 9.1091667 | AA4: 45237 | AB4: 45250 | AC4: 0.5 | AE4: 2022 | AF4: 2.2 | AM4: Long term Liability | AN4: =AN2-AN3 -> 3480.12 | BK4: 2021-04 | BL4: =(D4*100)-BR4 -> 27.349334 | BM4: 0.6491973 | BN4: 10.539244 | BO4: =BQ4-BR4 -> 1.195097 | BP4: 5.8040857 | BQ4: 1.4651031 | BR4: 0.27000609 | BU4: SUMMARY OUTPUT
A5: 44317 | B5: 754.25 | D5: =(B5-B4)/B4 -> 0.2082499 | F5: 44317 | G5: 15582.8 | H5: =(G5-G4)/G4 -> 0.065046374 | O5: 2021 | P5: 24.12 | AA5: 45049 | AB5: 45061 | AC5: 1.5 | AE5: 2023 | AF5: 2.6 | AP5: Estimated Yield of Long term Bond (%) | AQ5: =AQ2/AN4 -> 0.22777663 | AS5: Cost of Equity= | AV5: =AQ6+X4 -> 31.88683 | AX5: E: Market value of Equity | BA5: =AN6 -> 27365.51 | BF5: Last month | BG5: Last 3 months | BH5: Year to date | BI5: Since 01-Jan-1994 | BK5: 2021-05 | BL5: =(D5*100)-BR5 -> 20.54416 | BM5: 5.4578512 | BN5: 2.2742174 | BO5: =BQ5-BR5 -> 7.1317207 | BP5: 0.33800694 | BQ5: 7.4125512 | BR5: 0.28083045
A6: 44348 | B6: 760 | D6: =(B6-B5)/B5 -> 0.007623467 | F6: 44348 | G6: 15721.5 | H6: =(G6-G5)/G5 -> 0.0089008394 | O6: 2020 | P6: 14.9 | AA6: 44953 | AB6: 44965 | AC6: 0.6 | AE6: 2024 | AF6: 0.75 | AM6: Total Equity | AN6: 27365.51 | AQ6: =AQ5*100 -> 22.777663 | AR6: % | AV6: =AV5/100 -> 0.3188683 | AX6: V: Debt+Equity (E+D) | BA6: =AN2+AN6 -> 43509.09 | BE6: Market premium % | BF6: 2.744155 | BG6: -33.77817 | BH6: -33.77817 | BI6: 4.143206 | BK6: 2021-06 | BL6: =(D6*100)-BR6 -> 0.4845074 | BM6: 7.7699152 | BN6: 4.7403864 | BO6: =BQ6-BR6 -> 2.8089051 | BP6: -1.7305545 | BQ6: 3.0867444 | BR6: 0.2778393 | BU6: Regression Statistics
A7: 44378 | B7: 726.4 | D7: =(B7-B6)/B6 -> -0.044210526 | F7: 44378 | G7: 15763.05 | H7: =(G7-G6)/G6 -> 0.0026428776 | O7: 2019 | P7: 12.02 | AA7: 44693 | AB7: 44806 | AC7: 1 | AE7: Grand Total | AF7: 8.55 | AX7: r_e: Cost of Equity (CAPM) | BA7: =V4 -> 0.18046623 | BE7: SMB % | BF7: -25.923507 | BG7: -16.91952 | BH7: -16.91952 | BI7: -4.543637 | BK7: 2021-07 | BL7: =(D7*100)-BR7 -> -4.6986103 | BM7: 5.052861 | BN7: 6.7052357 | BO7: =BQ7-BR7 -> 1.4359835 | BP7: 3.4943011 | BQ7: 1.7135412 | BR7: 0.27755769 | BU7: Multiple R | BV7: 0.57079885
A8: 44409 | B8: 761.6 | D8: =(B8-B7)/B7 -> 0.04845815 | F8: 44409 | G8: 17132.2 | H8: =(G8-G7)/G7 -> 0.086858191 | O8: 2018 | P8: 3.15 | AA8: 44767 | AB8: 44776 | AC8: 0.4 | AX8: r_e: Cost of Equity (Bond Yield approach) | BA8: =AV6 -> 0.3188683 | BE8: HML % | BF8: 14.716229 | BG8: 21.71195 | BH8: 21.71195 | BI8: 6.552079 | BK8: 2021-08 | BL8: =(D8*100)-BR8 -> 4.5560008 | BM8: -8.3949225 | BN8: -6.9714962 | BO8: =BQ8-BR8 -> 5.4379455 | BP8: 3.9728501 | BQ8: 5.7277597 | BR8: 0.28981422 | BU8: R Square | BV8: 0.32581133
A9: 44440 | B9: 803.95 | D9: =(B9-B8)/B8 -> 0.055606618 | F9: 44440 | G9: 17618.15 | H9: =(G9-G8)/G8 -> 0.028364717 | O9: 2017 | P9: 28.65 | AA9: 44503 | AB9: 44517 | AC9: 0.5 | BE9: WML % | BF9: 15.962009 | BG9: -14.62498 | BH9: -14.62498 | BI9: 10.996853 | BK9: 2021-09 | BL9: =(D9*100)-BR9 -> 5.292827 | BM9: -1.4727894 | BN9: 10.66231 | BO9: =BQ9-BR9 -> 3.8451046 | BP9: -2.2344153 | BQ9: 4.1129394 | BR9: 0.26783476 | BU9: Adjusted R Square | BV9: 0.18387688
A10: 44470 | B10: 802.85 | D10: =(B10-B9)/B9 -> -0.0013682443 | F10: 44470 | G10: 17671.65 | H10: =(G10-G9)/G9 -> 0.0030366412 | O10: 2016 | P10: 3.01 | AA10: 44361 | AB10: 44454 | AC10: 0.5 | AX10: D: Value of Debt | BA10: =AN2 -> 16143.58 | BK10: 2021-10 | BL10: =(D10*100)-BR10 -> -0.40652078 | BM10: 1.7123054 | BN10: 0.60131906 | BO10: =BQ10-BR10 -> -1.3747763 | BP10: 6.6838387 | BQ10: -1.1050799 | BR10: 0.26969635 | BU10: Standard Error | BV10: 12.892225
A11: 44501 | B11: 789.15 | D11: =(B11-B10)/B10 -> -0.017064209 | F11: 44501 | G11: 16983.2 | H11: =(G11-G10)/G10 -> -0.038957879 | O11: 2015 | P11: -4.06 | AA11: 44767 | AB11: 44776 | AC11: 0.4 | AX11: r_d: Cost of Debt | BA11: =AQ5 -> 0.22777663 | BE11: Start Month | BF11: 34243 | BK11: 2021-11 | BL11: =(D11*100)-BR11 -> -2.0136881 | BM11: 1.9695719 | BN11: -1.6546471 | BO11: =BQ11-BR11 -> -1.3296586 | BP11: 4.569058 | BQ11: -1.0223913 | BR11: 0.30726727 | BU11: Observations | BV11: 24
A12: 44531 | B12: 990.75 | D12: =(B12-B11)/B11 -> 0.25546474 | F12: 44531 | G12: 17354.05 | H12: =(G12-G11)/G11 -> 0.021836285 | O12: 2014 | P12: 31.39 | AA12: 44503 | AB12: 44517 | AC12: 0.5 | AX12: Tax Rate | BA12: 0.25 | BE12: End Month | BF12: 44986 | BK12: 2021-12 | BL12: =(D12*100)-BR12 -> 25.248507 | BM12: 5.9782451 | BN12: 1.2897451 | BO12: =BQ12-BR12 -> 3.5273656 | BP12: 3.5805724 | BQ12: 3.8253328 | BR12: 0.29796728
A13: 44562 | B13: 963.5 | D13: =(B13-B12)/B12 -> -0.027504416 | F13: 44562 | G13: 17339.85 | H13: =(G13-G12)/G12 -> -0.0008182528 | O13: 2013 | P13: 6.76 | AA13: 44361 | AB13: 44454 | AC13: 0.5 | BB13: in Percentage (%) | BK13: 2022-01 | BL13: =(D13*100)-BR13 -> -3.0534749 | BM13: -0.2288274 | BN13: 10.931499 | BO13: =BQ13-BR13 -> -1.8761949 | BP13: -0.018796784 | BQ13: -1.5731616 | BR13: 0.30303333 | BU13: ANOVA
A14: 44593 | B14: 837.05 | D14: =(B14-B13)/B13 -> -0.13124027 | F14: 44593 | G14: 16793.9 | H14: =(G14-G13)/G13 -> -0.031485278 | O14: 2012 | P14: 27.7 | AA14: 44767 | AB14: 44776 | AC14: 0.4 | AX14: WACC (CAPM apporach) | BA14: =((BA5/BA6)*BA7)+((BA10/BA6)*BA11*(1-BA12)) -> 0.17689173 | BB14: =BA14*100 -> 17.689173 | BC14: % | BE14: Source:- https://web.iima.ac.in/~iffm/Indian-Fama-French-Momentum/index.php | BK14: 2022-02 | BL14: =(D14*100)-BR14 -> -13.409388 | BM14: -6.832612 | BN14: -1.8273542 | BO14: =BQ14-BR14 -> -4.710292 | BP14: -2.4552567 | BQ14: -4.4249312 | BR14: 0.28536076 | BV14: df | BW14: SS | BX14: MS | BY14: F | BZ14: Significance F
A15: 44621 | B15: 824.45 | D15: =(B15-B14)/B14 -> -0.015052864 | F15: 44621 | G15: 17464.75 | H15: =(G15-G14)/G14 -> 0.039946052 | O15: 2011 | P15: -24.62 | AA15: 44503 | AB15: 44517 | AC15: 0.5 | AX15: WACC (Bond Yield apporach) | BA15: =((BA5/BA6)*BA8)+((BA10/BA6)*BA11*(1-BA12)) -> 0.26394119 | BB15: =BA15*100 -> 26.394119 | BC15: % | BK15: 2022-03 | BL15: =(D15*100)-BR15 -> -1.8203812 | BM15: 2.110784 | BN15: 0.7905411 | BO15: =BQ15-BR15 -> 4.4190756 | BP15: 7.2255747 | BQ15: 4.7341704 | BR15: 0.31509482 | BU15: Regression | BV15: 4 | BW15: 1526.139 | BX15: 381.53474 | BY15: 2.2955056 | BZ15: 0.096760852
A16: 44652 | B16: 828.6 | D16: =(B16-B15)/B15 -> 0.0050336588 | F16: 44652 | G16: 17102.55 | H16: =(G16-G15)/G15 -> -0.020738917 | O16: 2010 | P16: 17.95 | AA16: 44361 | AB16: 44454 | AC16: 0.5 | BK16: 2022-04 | BL16: =(D16*100)-BR16 -> 0.19738443 | BM16: 2.1924603 | BN16: 4.4905873 | BO16: =BQ16-BR16 -> 1.0617866 | BP16: -2.9122357 | BQ16: 1.367768 | BR16: 0.30598145 | BU16: Residual | BV16: 19 | BW16: 3157.9798 | BX16: 166.20946
A17: 44682 | B17: 687.65 | D17: =(B17-B16)/B16 -> -0.1701062 | F17: 44682 | G17: 16584.55 | H17: =(G17-G16)/G16 -> -0.030287881 | O17: 2009 | P17: 75.76 | BK17: 2022-05 | BL17: =(D17*100)-BR17 -> -17.403469 | BM17: -3.4015396 | BN17: -2.2869047 | BO17: =BQ17-BR17 -> -6.9566241 | BP17: -6.0227346 | BQ17: -6.5637757 | BR17: 0.39284838 | BU17: Total | BV17: 23 | BW17: 4684.1188
A18: 44713 | B18: 610.1 | D18: =(B18-B17)/B17 -> -0.11277539 | F18: 44713 | G18: 15780.25 | H18: =(G18-G17)/G17 -> -0.048496944 | O18: 2008 | P18: -51.79 | BK18: 2022-06 | BL18: =(D18*100)-BR18 -> -11.680982 | BM18: 0.2137815 | BN18: -2.8098945 | BO18: =BQ18-BR18 -> -5.3456301 | BP18: 1.8592887 | BQ18: -4.942188 | BR18: 0.40344207
A19: 44743 | B19: 796.75 | D19: =(B19-B18)/B18 -> 0.30593345 | F19: 44743 | G19: 17158.25 | H19: =(G19-G18)/G18 -> 0.087324345 | O19: 2007 | P19: 54.77 | BK19: 2022-07 | BL19: =(D19*100)-BR19 -> 30.185226 | BM19: 2.2470931 | BN19: -3.3513363 | BO19: =BQ19-BR19 -> 7.8960624 | BP19: -2.8933446 | BQ19: 8.3041821 | BR19: 0.40811974 | BV19: Coefficients | BW19: Standard Error | BX19: t Stat | BY19: P-value | BZ19: Lower 95% | CA19: Upper 95% | CB19: Lower 95.0% | CC19: Upper 95.0%
A20: 44774 | B20: 777 | D20: =(B20-B19)/B19 -> -0.024788202 | F20: 44774 | G20: 17759.3 | H20: =(G20-G19)/G19 -> 0.035029796 | O20: 2006 | P20: 39.83 | BK20: 2022-08 | BL20: =(D20*100)-BR20 -> -2.956053 | BM20: 1.2287121 | BN20: 2.4731591 | BO20: =BQ20-BR20 -> 4.4127181 | BP20: 5.8556121 | BQ20: 4.8899509 | BR20: 0.47723275 | BU20: Intercept | BV20: 2.3165107 | BW20: 3.0085478 | BX20: 0.76997636 | BY20: 0.45078182 | BZ20: -3.9804523 | CA20: 8.6134736 | CB20: -3.9804523 | CC20: 8.6134736
A21: 44805 | B21: 751.15 | D21: =(B21-B20)/B20 -> -0.033268983 | F21: 44805 | G21: 17094.35 | H21: =(G21-G20)/G20 -> -0.037442354 | O21: 2005 | P21: 36.34 | BK21: 2022-09 | BL21: =(D21*100)-BR21 -> -3.8017741 | BM21: 3.2997202 | BN21: -2.0141931 | BO21: =BQ21-BR21 -> -4.0541134 | BP21: 1.4322461 | BQ21: -3.5792376 | BR21: 0.47487581 | BU21: SMB | BV21: 0.13085024 | BW21: 0.7802251 | BX21: 0.16770832 | BY21: 0.86858496 | BZ21: -1.5021797 | CA21: 1.7638801 | CB21: -1.5021797 | CC21: 1.7638801
A22: 44835 | B22: 759.95 | D22: =(B22-B21)/B21 -> 0.01171537 | F22: 44835 | G22: 18012.2 | H22: =(G22-G21)/G21 -> 0.053693179 | O22: 2004 | P22: 10.68 | BK22: 2022-10 | BL22: =(D22*100)-BR22 -> 0.65480546 | BM22: -2.5174924 | BN22: 3.2116556 | BO22: =BQ22-BR22 -> 1.3427251 | BP22: -0.11801266 | BQ22: 1.8594566 | BR22: 0.51673152 | BU22: HML | BV22: 0.02288942 | BW22: 0.61603879 | BX22: 0.037155809 | BY22: 0.97074839 | BZ22: -1.2664946 | CA22: 1.3122734 | CB22: -1.2664946 | CC22: 1.3122734
A23: 44866 | B23: 719.05 | D23: =(B23-B22)/B22 -> -0.05381933 | F23: 44866 | G23: 18758.35 | H23: =(G23-G22)/G22 -> 0.041424701 | O23: 2003 | P23: 71.9 | BK23: 2022-11 | BL23: =(D23*100)-BR23 -> -5.8969638 | BM23: -0.46622365 | BN23: 5.7887239 | BO23: =BQ23-BR23 -> 1.7868428 | BP23: -1.5132308 | BQ23: 2.3018736 | BR23: 0.51503079 | BU23: Rm-Rf | BV23: 1.8080718 | BW23: 0.67436026 | BX23: 2.681166 | BY23: 0.014777068 | BZ23: 0.39661958 | CA23: 3.2195241 | CB23: 0.39661958 | CC23: 3.2195241
A24: 44896 | B24: 679.45 | D24: =(B24-B23)/B23 -> -0.055072665 | F24: 44896 | G24: 18105.3 | H24: =(G24-G23)/G23 -> -0.03481383 | O24: 2002 | P24: 3.25 | BK24: 2022-12 | BL24: =(D24*100)-BR24 -> -6.0182976 | BM24: 1.6786937 | BN24: 3.1650308 | BO24: =BQ24-BR24 -> -4.4912733 | BP24: -0.085831971 | BQ24: -3.9802422 | BR24: 0.51103104 | BU24: WML | BV24: 0.12878169 | BW24: 0.793993 | BX24: 0.16219499 | BY24: 0.87286479 | BZ24: -1.5330648 | CA24: 1.7906281 | CB24: -1.5330648 | CC24: 1.7906281
A25: 44927 | B25: 593.6 | D25: =(B25-B24)/B24 -> -0.1263522 | F25: 44927 | G25: 17662.15 | H25: =(G25-G24)/G24 -> -0.024476258 | O25: 2001 | P25: -16.18 | BE25: Required Rate of Return according Fama-French Model = | BF25: =T3/12+BV23*X4+BV21*BI7+BV22*BI8+BV24*BI9+BV20 -> 20.299835 | BG25: % | BK25: 2023-01 | BL25: =(D25*100)-BR25 -> -13.179622 | BM25: 0.37775377 | BN25: 3.6494669 | BO25: =BQ25-BR25 -> -5.0937245 | BP25: -3.2653055 | BQ25: -4.5493222 | BR25: 0.54440229
A26: 44958 | B26: 645.15 | D26: =(B26-B25)/B25 -> 0.086842992 | F26: 44958 | G26: 17303.95 | H26: =(G26-G25)/G25 -> -0.020280657 | O26: 2000 | P26: -14.65 | BK26: 2023-02 | BL26: =(D26*100)-BR26 -> 8.187283 | BM26: -2.3195572 | BN26: 0.038092368 | BO26: =BQ26-BR26 -> -5.9589538 | BP26: -1.7739889 | BQ26: -5.4619376 | BR26: 0.49701615
A27: 44986 | B27: 865.35 | D27: =(B27-B26)/B26 -> 0.34131597 | F27: 44986 | G27: 17359.75 | H27: =(G27-G26)/G26 -> 0.0032246973 | O27: Source | BK27: 2023-03 | BL27: =(D27*100)-BR27 -> 33.566538 | BM27: -2.5146541 | BN27: 1.1720531 | BO27: =BQ27-BR27 -> -0.33502744 | BP27: 1.2648428 | BQ27: 0.23003149 | BR27: 0.56505892
A28: 45017 | B28: 1129.3 | D28: =(B28-B27)/B27 -> 0.30502109 | F28: 45017 | G28: 18065 | H28: =(G28-G27)/G27 -> 0.040625585 | O28: https://primeinvestor.in/nifty-50-returns/
A29: 45047 | B29: 1166 | D29: =(B29-B28)/B28 -> 0.032498008 | F29: 45047 | G29: 18534.4 | H29: =(G29-G28)/G28 -> 0.025983947 | BE29: Disclaimer:- The required Rate of return calculated from Fama French Theory may not be entirely accurate as we were unable to find the value unable to find the values of SMB,HML, and WML beyond March 2023.
A30: 45078 | B30: 1030 | D30: =(B30-B29)/B29 -> -0.11663808 | F30: 45078 | G30: 19189.05 | H30: =(G30-G29)/G29 -> 0.035320809
A31: 45108 | B31: 974.9 | D31: =(B31-B30)/B30 -> -0.053495146 | F31: 45108 | G31: 19753.8 | H31: =(G31-G30)/G30 -> 0.029430847
A32: 45139 | B32: 1004.95 | D32: =(B32-B31)/B31 -> 0.030823674 | F32: 45139 | G32: 19253.8 | H32: =(G32-G31)/G31 -> -0.025311586
A33: 45170 | B33: 884.85 | D33: =(B33-B32)/B32 -> -0.11950843 | F33: 45170 | G33: 19638.3 | H33: =(G33-G32)/G32 -> 0.019970084
A34: 45200 | B34: 883.55 | D34: =(B34-B33)/B33 -> -0.0014691756 | F34: 45200 | G34: 19079.6 | H34: =(G34-G33)/G33 -> -0.028449509
A35: 45231 | B35: 986.6 | D35: =(B35-B34)/B34 -> 0.11663177 | F35: 45231 | G35: 20133.15 | H35: =(G35-G34)/G34 -> 0.055218663 | BE35: HML = high-minus-low factor
A36: 45261 | B36: 1052.05 | D36: =(B36-B35)/B35 -> 0.066338942 | F36: 45261 | G36: 21731.4 | H36: =(G36-G35)/G35 -> 0.079384001 | BE36: SMB = the small-minus-big factor
A37: 45292 | B37: 949.3 | D37: =(B37-B36)/B36 -> -0.097666461 | F37: 45292 | G37: 21725.7 | H37: =(G37-G36)/G36 -> -0.00026229327 | BE37: WML = Winner Minus Loser (adds momentum dimension)
A38: 45323 | B38: 956.3 | D38: =(B38-B37)/B37 -> 0.0073738544 | F38: 45323 | G38: 21982.8 | H38: =(G38-G37)/G37 -> 0.011833911
A39: 45352 | B39: 870.45 | D39: =(B39-B38)/B38 -> -0.089773084 | F39: 45352 | G39: 22326.9 | H39: =(G39-G38)/G38 -> 0.015653147
A40: 45383 | B40: 832.55 | D40: =(B40-B39)/B39 -> -0.043540697 | F40: 45383 | G40: 22604.85 | H40: =(G40-G39)/G39 -> 0.012449108
...

Sheet CAPM (Weekly) (Part-1)
A1: Data for Anupam Rasayan | D1: Returns | F1: DATA for NIFTY 50 | H1: Return | O1: Merket Returns for NIFTY 50 | S1: Average Return | T1: 91 day T-bill | U1: Cost of Equity
A2: Date | B2: Close | F2: Date | G2: Close | J2: Covariance | K2: Variance | L2: Beta | O2: 2024 | T2: (Risk free Rate) | U2: (CAPM)
A3: 44279 | B3: 495.7 | F3: 44277 | G3: 14507.3 | J3: =_xlfn.COVARIANCE.P(D4:D195,H4:H195) -> 0.00020553315 | K3: =_xlfn.VAR.P(H4:H195) -> 0.00031883116 | L3: =J3/K3 -> 0.64464575 | O3: 2023 | P3: 19.42 | S3: 15.609167 | T3: 6.5 | U3: =U4*100 -> 12.372186
A4: 44285 | B4: 516.95 | D4: =(B4-B3)/B3 -> 0.042868671 | F4: 44285 | G4: 14867.35 | H4: =(G4-G3)/G3 -> 0.02481854 | O4: 2022 | P4: 4.32 | S4: =S3/100 -> 0.15609167 | T4: =T3/100 -> 0.065 | U4: =T4+L3*(S4-T4) -> 0.12372186
A5: 44291 | B5: 555.25 | D5: =(B5-B4)/B4 -> 0.074088403 | F5: 44291 | G5: 14834.85 | H5: =(G5-G4)/G4 -> -0.0021859982 | O5: 2021 | P5: 24.12
A6: 44298 | B6: 579.95 | D6: =(B6-B5)/B5 -> 0.044484466 | F6: 44298 | G6: 14617.85 | H6: =(G6-G5)/G5 -> -0.014627718 | O6: 2020 | P6: 14.9
A7: 44305 | B7: 590 | D7: =(B7-B6)/B6 -> 0.01732908 | F7: 44305 | G7: 14341.35 | H7: =(G7-G6)/G6 -> -0.01891523 | O7: 2019 | P7: 12.02
A8: 44312 | B8: 624.25 | D8: =(B8-B7)/B7 -> 0.058050847 | F8: 44312 | G8: 14631.1 | H8: =(G8-G7)/G7 -> 0.020203816 | O8: 2018 | P8: 3.15
A9: 44319 | B9: 721.1 | D9: =(B9-B8)/B8 -> 0.15514618 | F9: 44319 | G9: 14823.15 | H9: =(G9-G8)/G8 -> 0.013126149 | O9: 2017 | P9: 28.65
A10: 44326 | B10: 734.45 | D10: =(B10-B9)/B9 -> 0.018513382 | F10: 44326 | G10: 14677.8 | H10: =(G10-G9)/G9 -> -0.0098056081 | O10: 2016 | P10: 3.01
A11: 44333 | B11: 769.4 | D11: =(B11-B10)/B10 -> 0.047586629 | F11: 44333 | G11: 15175.3 | H11: =(G11-G10)/G10 -> 0.033894725 | O11: 2015 | P11: -4.06
A12: 44340 | B12: 761.5 | D12: =(B12-B11)/B11 -> -0.010267741 | F12: 44340 | G12: 15435.65 | H12: =(G12-G11)/G11 -> 0.017156168 | O12: 2014 | P12: 31.39
A13: 44347 | B13: 769.25 | D13: =(B13-B12)/B12 -> 0.010177282 | F13: 44347 | G13: 15670.25 | H13: =(G13-G12)/G12 -> 0.015198583 | O13: 2013 | P13: 6.76
A14: 44354 | B14: 777.65 | D14: =(B14-B13)/B13 -> 0.010919727 | F14: 44354 | G14: 15799.35 | H14: =(G14-G13)/G13 -> 0.0082385412 | O14: 2012 | P14: 27.7
A15: 44361 | B15: 733.2 | D15: =(B15-B14)/B14 -> -0.05715939 | F15: 44361 | G15: 15683.35 | H15: =(G15-G14)/G14 -> -0.0073420742 | O15: 2011 | P15: -24.62
A16: 44368 | B16: 745.25 | D16: =(B16-B15)/B15 -> 0.016434806 | F16: 44368 | G16: 15860.35 | H16: =(G16-G15)/G15 -> 0.011285854 | O16: 2010 | P16: 17.95
... A26: 44438 | B26: 754.7 | D26: =(B26-B25)/B25 -> 0.024155245 | F26: 44438 | G26: 17323.6 | H26: =(G26-G25)/G25 -> 0.037018413 | O26: 2000 | P26: -14.65
A27: 44445 | B27: 751.4 | D27: =(B27-B26)/B26 -> -0.0043725984 | F27: 44445 | G27: 17369.25 | H27: =(G27-G26)/G26 -> 0.0026351336 | O27: Source
A28: 44452 | B28: 761 | D28: =(B28-B27)/B27 -> 0.012776151 | F28: 44452 | G28: 17585.15 | H28: =(G28-G27)/G27 -> 0.012430013 | O28: https://primeinvestor.in/nifty-50-returns/
A29: 44459 | B29: 758.85 | D29: =(B29-B28)/B28 -> -0.00282523 | F29: 44459 | G29: 17853.2 | H29: =(G29-G28)/G28 -> 0.015242975
A30: 44466 | B30: 781.35 | D30: =(B30-B29)/B29 -> 0.029650128 | F30: 44466 | G30: 17532.05 | H30: =(G30-G29)/G29 -> -0.017988372
A31: 44473 | B31: 784.2 | D31: =(B31-B30)/B30 -> 0.0036475331 | F31: 44473 | G31: 17895.2 | H31: =(G31-G30)/G30 -> 0.020713493
A32: 44480 | B32: 813.3 | D32: =(B32-B31)/B31 -> 0.037107881 | F32: 44480 | G32: 18338.55 | H32: =(G32-G31)/G31 -> 0.0247748
A33: 44487 | B33: 802.35 | D33: =(B33-B32)/B32 -> -0.013463667 | F33: 44487 | G33: 18114.9 | H33: =(G33-G32)/G32 -> -0.012195621
A34: 44494 | B34: 802.85 | D34: =(B34-B33)/B33 -> 0.00062316944 | F34: 44494 | G34: 17671.65 | H34: =(G34-G33)/G33 -> -0.024468807
A35: 44501 | B35: 805.05 | D35: =(B35-B34)/B34 -> 0.0027402379 | F35: 44501 | G35: 17916.8 | H35: =(G35-G34)/G34 -> 0.013872502
A36: 44508 | B36: 820.35 | D36: =(B36-B35)/B35 -> 0.019005031 | F36: 44508 | G36: 18102.75 | H36: =(G36-G35)/G35 -> 0.010378527
A37: 44515 | B37: 815.05 | D37: =(B37-B36)/B36 -> -0.006460657 | F37: 44515 | G37: 17764.8 | H37: =(G37-G36)/G36 -> -0.018668434
A38: 44522 | B38: 790.8 | D38: =(B38-B37)/B37 -> -0.029752776 | F38: 44522 | G38: 17026.45 | H38: =(G38-G37)/G37 -> -0.041562528
A39: 44529 | B39: 800.55 | D39: =(B39-B38)/B38 -> 0.012329287 | F39: 44529 | G39: 17196.7 | H39: =(G39-G38)/G38 -> 0.0099991484
A40: 44536 | B40: 823.05 | D40: =(B40-B39)/B39 -> 0.028105677 | F40: 44536 | G40: 17511.3 | H40: =(G40-G39)/G39 -> 0.018294208
... A195: 45621 | B195: 728.65 | D195: =(B195-B194)/B194 -> -0.0062056738 | F195: 45621 | G195: 24221.9 | H195: =(G195-G194)/G194 -> 0.01316128

Sheet CAPM (Daily) (Part-1)
A1: Data for Anupam Rasayan | D1: Returns | F1: DATA for NIFTY 50 | H1: Return | O1: Merket Returns for NIFTY 50 | S1: Average Return | T1: 91 day T-bill | U1: Cost of Equity
A2: Date | B2: Close | F2: Date | G2: Close | J2: Covariance | K2: Variance | L2: Beta | O2: 2024 | T2: (Risk free Rate) | U2: (CAPM)
A3: 3/24/2021 | B3: 526.8 | F3: 3/24/2021 | G3: 14549.4 | J3: =_xlfn.COVARIANCE.P(D4:D47,H4:H47) -> 8.4944211e-05 | K3: =_xlfn.VAR.P(H4:H47) -> 0.00012664872 | L3: =J3/K3 -> 0.67070724 | O3: 2023 | P3: 19.42 | S3: 15.609167 | T3: 6.5 | U3: =U4*100 -> 12.609584
A4: 3/25/2021 | B4: 494.75 | D4: =(B4-B3)/B3 -> -0.060839028 | F4: 3/25/2021 | G4: 14324.9 | H4: =(G4-G3)/G3 -> -0.01543019 | O4: 2022 | P4: 4.32 | S4: =S3/100 -> 0.15609167 | T4: =T3/100 -> 0.065 | U4: =T4+L3*(S4-T4) -> 0.12609584
A5: 3/26/2021 | B5: 495.7 | D5: =(B5-B4)/B4 -> 0.0019201617 | F5: 3/26/2021 | G5: 14507.3 | H5: =(G5-G4)/G4 -> 0.012733073 | O5: 2021 | P5: 24.12
A6: 3/30/2021 | B6: 480.3 | D6: =(B6-B5)/B5 -> -0.031067178 | F6: 3/30/2021 | G6: 14845.1 | H6: =(G6-G5)/G5 -> 0.023284829 | O6: 2020 | P6: 14.9
A7: 3/31/2021 | B7: 489.15 | D7: =(B7-B6)/B6 -> 0.018425984 | F7: 3/31/2021 | G7: 14690.7 | H7: =(G7-G6)/G6 -> -0.010400738 | O7: 2019 | P7: 12.02
A8: 44200 | B8: 516.95 | D8: =(B8-B7)/B7 -> 0.056833282 | F8: 44200 | G8: 14867.35 | H8: =(G8-G7)/G7 -> 0.012024614 | O8: 2018 | P8: 3.15
A9: 44320 | B9: 540.95 | D9: =(B9-B8)/B8 -> 0.046426153 | F9: 44320 | G9: 14637.8 | H9: =(G9-G8)/G8 -> -0.015439873 | O9: 2017 | P9: 28.65
A10: 44351 | B10: 552.1 | D10: =(B10-B9)/B9 -> 0.020611886 | F10: 44351 | G10: 14683.5 | H10: =(G10-G9)/G9 -> 0.0031220539 | O10: 2016 | P10: 3.01
A11: 44381 | B11: 557.4 | D11: =(B11-B10)/B10 -> 0.0095997102 | F11: 44381 | G11: 14819.05 | H11: =(G11-G10)/G10 -> 0.0092314503 | O11: 2015 | P11: -4.06
A12: 44412 | B12: 552.65 | D12: =(B12-B11)/B11 -> -0.0085217079 | F12: 44412 | G12: 14873.8 | H12: =(G12-G11)/G11 -> 0.0036945688 | O12: 2014 | P12: 31.39
A13: 44443 | B13: 555.25 | D13: =(B13-B12)/B12 -> 0.0047046051 | F13: 44443 | G13: 14834.85 | H13: =(G13-G12)/G12 -> -0.0026186987 | O13: 2013 | P13: 6.76
A14: 44534 | B14: 553.65 | D14: =(B14-B13)/B13 -> -0.0028815849 | F14: 44534 | G14: 14310.8 | H14: =(G14-G13)/G13 -> -0.035325602 | O14: 2012 | P14: 27.7
A15: 4/13/2021 | B15: 580.4 | D15: =(B15-B14)/B14 -> 0.048315723 | F15: 4/13/2021 | G15: 14504.8 | H15: =(G15-G14)/G14 -> 0.013556195 | O15: 2011 | P15: -24.62
A16: 4/15/2021 | B16: 594.7 | D16: =(B16-B15)/B15 -> 0.024638181 | F16: 4/15/2021 | G16: 14581.45 | H16: =(G16-G15)/G15 -> 0.0052844576 | O16: 2010 | P16: 17.95
A17: 4/16/2021 | B17: 579.95 | D17: =(B17-B16)/B16 -> -0.024802421 | F17: 4/16/2021 | G17: 14617.85 | H17: =(G17-G16)/G16 -> 0.0024963224 | O17: 2009 | P17: 75.76
A18: 4/19/2021 | B18: 552.05 | D18: =(B18-B17)/B17 -> -0.048107595 | F18: 4/19/2021 | G18: 14359.45 | H18: =(G18-G17)/G17 -> -0.017677018 | O18: 2008 | P18: -51.79
A19: 4/20/2021 | B19: 556.55 | D19: =(B19-B18)/B18 -> 0.0081514356 | F19: 4/20/2021 | G19: 14296.4 | H19: =(G19-G18)/G18 -> -0.0043908367 | O19: 2007 | P19: 54.77
A20: 4/22/2021 | B20: 554.4 | D20: =(B20-B19)/B19 -> -0.0038630851 | F20: 4/22/2021 | G20: 14406.15 | H20: =(G20-G19)/G19 -> 0.0076767578 | O20: 2006 | P20: 39.83
A21: 4/23/2021 | B21: 590 | D21: =(B21-B20)/B20 -> 0.064213564 | F21: 4/23/2021 | G21: 14341.35 | H21: =(G21-G20)/G20 -> -0.0044980789 | O21: 2005 | P21: 36.34
A22: 4/26/2021 | B22: 602.55 | D22: =(B22-B21)/B21 -> 0.021271186 | F22: 4/26/2021 | G22: 14485 | H22: =(G22-G21)/G21 -> 0.010016491 | O22: 2004 | P22: 10.68
A23: 4/27/2021 | B23: 629.6 | D23: =(B23-B22)/B22 -> 0.04489254 | F23: 4/27/2021 | G23: 14653.05 | H23: =(G23-G22)/G22 -> 0.011601657 | O23: 2003 | P23: 71.9
A24: 4/28/2021 | B24: 640 | D24: =(B24-B23)/B23 -> 0.016518424 | F24: 4/28/2021 | G24: 14864.55 | H24: =(G24-G23)/G23 -> 0.014433855 | O24: 2002 | P24: 3.25
A25: 4/29/2021 | B25: 632.2 | D25: =(B25-B24)/B24 -> -0.0121875 | F25: 4/29/2021 | G25: 14894.9 | H25: =(G25-G24)/G24 -> 0.0020417705 | O25: 2001 | P25: -16.18
A26: 4/30/2021 | B26: 624.25 | D26: =(B26-B25)/B25 -> -0.012575134 | F26: 4/30/2021 | G26: 14631.1 | H26: =(G26-G25)/G25 -> -0.01771076 | O26: 2000 | P26: -14.65
A27: 44260 | B27: 629.55 | D27: =(B27-B26)/B26 -> 0.0084901882 | F27: 44260 | G27: 14634.15 | H27: =(G27-G26)/G26 -> 0.00020846006 | O27: Source
A28: 44291 | B28: 636.55 | D28: =(B28-B27)/B27 -> 0.011119053 | F28: 44291 | G28: 14496.5 | H28: =(G28-G27)/G27 -> -0.009406081 | O28: https://primeinvestor.in/nifty-50-returns/
A29: 44321 | B29: 682.85 | D29: =(B29-B28)/B28 -> 0.072735842 | F29: 44321 | G29: 14617.85 | H29: =(G29-G28)/G28 -> 0.0083709861
A30: 44352 | B30: 703.9 | D30: =(B30-B29)/B29 -> 0.030826682 | F30: 44352 | G30: 14724.8 | H30: =(G30-G29)/G29 -> 0.0073163974
A31: 44382 | B31: 721.1 | D31: =(B31-B30)/B30 -> 0.024435289 | F31: 44382 | G31: 14823.15 | H31: =(G31-G30)/G30 -> 0.0066792079
A32: 44474 | B32: 736.15 | D32: =(B32-B31)/B31 -> 0.020870892 | F32: 44474 | G32: 14942.35 | H32: =(G32-G31)/G31 -> 0.0080414757
A33: 44505 | B33: 729.9 | D33: =(B33-B32)/B32 -> -0.0084901175 | F33: 44505 | G33: 14850.75 | H33: =(G33-G32)/G32 -> -0.0061302272
A34: 44535 | B34: 728.5 | D34: =(B34-B33)/B33 -> -0.001918071 | F34: 44535 | G34: 14696.5 | H34: =(G34-G33)/G33 -> -0.010386681
A35: 5/14/2021 | B35: 734.45 | D35: =(B35-B34)/B34 -> 0.0081674674 | F35: 5/14/2021 | G35: 14677.8 | H35: =(G35-G34)/G34 -> -0.0012724118
A36: 5/17/2021 | B36: 755.85 | D36: =(B36-B35)/B35 -> 0.02913745 | F36: 5/17/2021 | G36: 14923.15 | H36: =(G36-G35)/G35 -> 0.01671572
A37: 5/18/2021 | B37: 767.75 | D37: =(B37-B36)/B36 -> 0.015743865 | F37: 5/18/2021 | G37: 15108.1 | H37: =(G37-G36)/G36 -> 0.012393496
A38: 5/19/2021 | B38: 771.5 | D38: =(B38-B37)/B37 -> 0.0048844025 | F38: 5/19/2021 | G38: 15030.15 | H38: =(G38-G37)/G37 -> -0.005159484
A39: 5/20/2021 | B39: 771.55 | D39: =(B39-B38)/B38 -> 6.4808814e-05 | F39: 5/20/2021 | G39: 14906.05 | H39: =(G39-G38)/G38 -> -0.0082567373
A40: 5/21/2021 | B40: 769.4 | D40: =(B40-B39)/B39 -> -0.0027865984 | F40: 5/21/2021 | G40: 15175.3 | H40: =(G40-G39)/G39 -> 0.018063135
...

Sheet Part-2 (Balance Sheet)
D1: Financial Year | N1: Capital Structure and Debt Analysis
C2: 2018 | D2: 2019 | E2: 2020 | F2: 2021 | G2: 2022 | H2: 2023 | I2: 2024
Q3: FY | R3: 2019 | S3: 2020 | T3: 2021 | U3: 2022 | V3: 2023 | W3: 2024
A4: Balance Sheet | C4: Shares outstanding numbers in cr. Other numbers in ₹ cr | O4: Proportion of Debt vs. Equity
A5: Statements | P5: Debt Ratio | R5: =D36/D22 -> 0.61655198 | S5: =E36/E22 -> 0.6433653 | T5: =F36/F22 -> 0.31531767 | U5: =G36/G22 -> 0.40258981 | V5: =H36/H22 -> 0.33612411 | W5: =I36/I22 -> 0.36313121
A6: Current Assests | D6: 423.46 | E6: 551.75 | F6: 1090.47 | G6: 1446.64 | H6: 2111.2 | I6: 2226.62 | P6: Equity Ratio | R6: =D38/D22 -> 0.38344802 | S6: =E38/E22 -> 0.3566347 | T6: =F38/F22 -> 0.68468233 | U6: =G38/G22 -> 0.59741019 | V6: =H38/H22 -> 0.66387589 | W6: =I38/I22 -> 0.63686879
P7: Current Ratio | R7: =D6/D24 -> 1.2476356 | S7: =E6/E24 -> 1.1169254 | T7: =F6/F24 -> 2.5926534 | U7: =G6/G24 -> 2.4310826 | V7: =H6/H24 -> 2.6038481 | W7: =I6/I24 -> 1.6929639
B8: Cash and Short term investments | D8: 7.06 | E8: 26.83 | F8: 295.71 | G8: 209.71 | H8: 629.92 | I8: 354.43
B9: Total Recivables | D9: 120.59 | E9: 129.49 | F9: 205.49 | G9: 280.1 | H9: 415.08 | I9: 579.39
B10: Total Inventory | D10: 195.37 | E10: 297.04 | F10: 492.22 | G10: 863.19 | H10: 931.47 | I10: 1055.32
B11: Other Current Assets | D11: 100.44 | E11: 98.39 | F11: 97.05 | G11: 93.64 | H11: 134.73 | I11: 237.48
A12: +
A13: Non Current Assets | D13: 899.04 | E13: 1112.53 | F13: 1207.53 | G13: 1443.92 | H13: 1666.72 | I13: 2375.05
B15: Loans & Advances | D15: 0 | E15: 0 | F15: 0 | G15: 0 | H15: 0 | I15: 0
B16: Net Property/Plant/Equipment | D16: 871.51 | E16: 1078.29 | F16: 1158.28 | G16: 1245.94 | H16: 1414.37 | I16: 1987.55
B17: Goodwill & Intangibles | D17: 0 | E17: 0 | F17: 0 | G17: 0 | H17: 123.21 | I17: 123.21
B18: Long Term Investments | D18: 0.4 | E18: 0.4 | F18: 0.02 | G18: 148.82 | H18: 1.42 | I18: 1.45
B19: Deferred Tax Assets (Net) | D19: 0 | E19: 0 | F19: 0 | G19: 0 | H19: 0 | I19: 0
B20: Other Assets | D20: 27.13 | E20: 33.84 | F20: 49.23 | G20: 49.16 | H20: 127.73 | I20: 262.85
A21: =
A22: Total Assets | D22: 1322.5 | E22: 1664.28 | F22: 2298 | G22: 2890.56 | H22: 3777.92 | I22: 4601.67
A24: Current Liability | D24: 339.41 | E24: 493.99 | F24: 420.6 | G24: 595.06 | H24: 810.8 | I24: 1315.22
B26: Accounts Payable | D26: 126.88 | E26: 183.02 | F26: 229.72 | G26: 246.63 | H26: 324.94 | I26: 437.13 | Q26: FY | R26: =R3 -> 2019 | S26: =S3 -> 2020 | T26: =T3 -> 2021 | U26: =U3 -> 2022 | V26: =V3 -> 2023 | W26: =W3 -> 2024
B27: Total Deposits | D27: 0 | E27: 0 | F27: 0 | G27: 0 | H27: 0 | I27: 0 | O27: Company’s Ability to Service its Debt
B28: Other Current Liabilities | D28: 212.53 | E28: 310.97 | F28: 190.88 | G28: 348.43 | H28: 485.86 | I28: 878.09 | P28: Interest Coverage Ratio | R28: =C81/C83 -> 2.4591479 | S28: =D81/D83 -> 3.6989733 | T28: =E81/E83 -> 2.5832965 | U28: =F81/F83 -> 2.4591479 | V28: =G81/G83 -> 8.1959131 | W28: =H81/H83 -> 5.91015
A29: +
A30: Non-Current Liabilities | D30: 475.98 | E30: 576.75 | F30: 304 | G30: 568.65 | H30: 459.05 | I30: 355.79
B32: Total Long Term Debt | D32: 462.31 | E32: 524.73 | F32: 279.63 | G32: 513.98 | H32: 381.92 | I32: 237.92
B33: Deferred Tax Liabilities (Net) | D33: 13.69 | E33: 19.08 | F33: 24.38 | G33: 54.65 | H33: 76.03 | I33: 116.39
B34: Other Liabilities | D34: -0.02 | E34: 32.94 | F34: -0.01 | G34: 0.02 | H34: 1.1 | I34: 1.48
A35: =
A36: Total Liabilities | D36: 815.39 | E36: 1070.74 | F36: 724.6 | G36: 1163.71 | H36: 1269.85 | I36: 1671.01
A38: Total Equity | D38: 507.11 | E38: 593.54 | F38: 1573.4 | G38: 1726.85 | H38: 2508.07 | I38: 2930.66
B40: Common Stock | D40: 74.63 | E40: 78.13 | F40: 99.92 | G40: 100.25 | H40: 107.47 | I40: 109.79
B41: Additional Paid-in Capital | D41: 210.88 | E41: 242.75 | F41: 1130.65 | G41: 1137.19 | H41: 1611.52 | I41: 1807.9
B42: Reserves & Surplus | D42: 221.6 | E42: 272.66 | F42: 342.83 | G42: 489.41 | H42: 653.6 | I42: 750.84
B43: Minority Interest | D43: 0 | E43: 0 | F43: 0 | G43: 0 | H43: 135.48 | I43: 169.63
B44: Other Equity | D44: 0 | E44: 0 | F44: 0 | G44: 0 | H44: 0 | I44: 92.5
A46: Total Liability and SE | D46: 1322.5 | E46: 1664.28 | F46: 2298 | G46: 2890.56 | H46: 3777.92 | I46: 4601.67 | O46: Dividend Policy
Q47: FY | R47: =R26 -> 2019 | S47: =S26 -> 2020 | T47: =T26 -> 2021 | U47: =U26 -> 2022 | V47: =V26 -> 2023 | W47: =W26 -> 2024
...

Sheet Part-3
A1: Parameters | B1: Ranking (1-5) | C1: Justification
A2: Financial Obligations | B2: 5 | C2: The company has a strong current ratio and interest coverage ratio, indicating good liquidity and solvency.
A3: Returns to Shareholders | B3: 2 | C3: The firm's ROE is average compared to it's peers, and has a moderate dividend yield compared to its peers.
A4: Stock Price Stability | B4: 2 | C4: The stock has a higher volatility (1.267) than the market.
A5: Growth in Revenue and Earnings | B5: 5 | C5: The firm has shown consistent earnings and sales growth above industry average.
A6: Environmental and Social Initiatives | B6: 3 | C6: The firm has taken a keen interest in meeting regulatory compliances and improving the lives of the community and employee alike.
A9: Parameters (Justifications)
A10: 1.) Financial Obligations | C10: The company's interest coverage ratio, Equity ratio shows an upwards trend while Debt ratio shows a downward trend this shows that every year the firm's equity is increasing faster than it's debt imporving its financial position and improving its ability to service it's debt. | E10: ='Part-2 (Balance Sheet)'!Q3 -> FY | F10: ='Part-2 (Balance Sheet)'!R3 -> 2019 | G10: ='Part-2 (Balance Sheet)'!S3 -> 2020 | H10: ='Part-2 (Balance Sheet)'!T3 -> 2021 | I10: ='Part-2 (Balance Sheet)'!U3 -> 2022 | J10: ='Part-2 (Balance Sheet)'!V3 -> 2023 | K10: ='Part-2 (Balance Sheet)'!W3 -> 2024
D11: ='Part-2 (Balance Sheet)'!P5 -> Debt Ratio | F11: ='Part-2 (Balance Sheet)'!R5 -> 0.61655198 | G11: ='Part-2 (Balance Sheet)'!S5 -> 0.6433653 | H11: ='Part-2 (Balance Sheet)'!T5 -> 0.31531767 | I11: ='Part-2 (Balance Sheet)'!U5 -> 0.40258981 | J11: ='Part-2 (Balance Sheet)'!V5 -> 0.33612411 | K11: ='Part-2 (Balance Sheet)'!W5 -> 0.36313121
D12: ='Part-2 (Balance Sheet)'!P6 -> Equity Ratio | F12: ='Part-2 (Balance Sheet)'!R6 -> 0.38344802 | G12: ='Part-2 (Balance Sheet)'!S6 -> 0.3566347 | H12: ='Part-2 (Balance Sheet)'!T6 -> 0.68468233 | I12: ='Part-2 (Balance Sheet)'!U6 -> 0.59741019 | J12: ='Part-2 (Balance Sheet)'!V6 -> 0.66387589 | K12: ='Part-2 (Balance Sheet)'!W6 -> 0.63686879
D13: ='Part-2 (Balance Sheet)'!P7 -> Current Ratio | F13: ='Part-2 (Balance Sheet)'!R7 -> 1.2476356 | G13: ='Part-2 (Balance Sheet)'!S7 -> 1.1169254 | H13: ='Part-2 (Balance Sheet)'!T7 -> 2.5926534 | I13: ='Part-2 (Balance Sheet)'!U7 -> 2.4310826 | J13: ='Part-2 (Balance Sheet)'!V7 -> 2.6038481 | K13: ='Part-2 (Balance Sheet)'!W7 -> 1.6929639
D14: ='Part-2 (Balance Sheet)'!P28 -> Interest Coverage Ratio | F14: ='Part-2 (Balance Sheet)'!R28 -> 2.4591479 | G14: ='Part-2 (Balance Sheet)'!S28 -> 3.6989733 | H14: ='Part-2 (Balance Sheet)'!T28 -> 2.5832965 | I14: ='Part-2 (Balance Sheet)'!U28 -> 2.4591479 | J14: ='Part-2 (Balance Sheet)'!V28 -> 8.1959131 | K14: ='Part-2 (Balance Sheet)'!W28 -> 5.91015
A33: 2.) Returns to Shareholders
C34: The firm's dividend yield (0.17) is much less than most of it's peer in speciality chemical sector and so is it's ROE of 5. | E34: Ratio | G34: P/E | H34: ROE | I34: ROCE | J34: Dividend Yield | K34: Sales Growth (5 years) | L34: EBIDT Growth 5 years | M34: Profit Growth 5 years | N34: EPS (3 years) | O34: EPS(5 years)
D35: Competitors
D37: Gujarat Fluorochemicals Ltd | G37: 102 | H37: 7.69 | I37: 9.76 | J37: 0.08 | K37: 9.42 | L37: 3.31 | M37: -18.8 | N37: 59.1 | O37: -
D38: Vinati Organics Ltd | G38: 51.1 | H38: 13.8 | I38: 18.5 | J38: 0.38 | K38: 11 | L38: 2.31 | M38: 2.72 | N38: 5.98 | O38: 2.55
D39: Akzo Nobel India Ltd | G39: 38.1 | H39: 32.3 | I39: 42.3 | J39: 2.06 | K39: 6.3 | L39: 13.3 | M39: 17.2 | N39: 26.8 | O39: 17.2
D40: Navin Fluorine International Ltd | G40: 76.2 | H40: 10.1 | I40: 10.4 | J40: 0.36 | K40: 15.7 | L40: 12.5 | M40: 9.35 | N40: -2.24 | O40: 9.3
D41: Fine Organic Industries Ltd | G41: 40.8 | H41: 21.7 | I41: 29 | J41: 0.19 | K41: 13.3 | L41: 17.9 | M41: 23.3 | N41: 47.4 | O41: 23.3
D42: Aarti Industries Ltd | G42: 35.3 | H42: 8.22 | I42: 7.47 | J42: 0.23 | K42: 8.86 | L42: 0.48 | M42: -3.07 | N42: -8.3 | O42: -3.92
D43: Supreme Petrochem Ltd | G43: 31.6 | H43: 16.8 | I43: 22.5 | J43: 1.3 | K43: 10.5 | L43: 37.6 | M43: 45.9 | N43: -12 | O43: 46.7
F45: Average | G45: =AVERAGE(G37:G43) -> 53.585714 | H45: =AVERAGE(H37:H43) -> 15.801429 | I45: =AVERAGE(I37:I43) -> 19.99 | J45: =AVERAGE(J37:J43) -> 0.65714286 | K45: =AVERAGE(K37:K43) -> 10.725714 | L45: =AVERAGE(L37:L43) -> 12.485714 | M45: =AVERAGE(M37:M43) -> 10.942857 | N45: =AVERAGE(N37:N43) -> 16.677143 | O45: =AVERAGE(O37:O43) -> 15.855
D47: Anupam Rasayan | G47: 115 | H47: 5 | I47: 9 | J47: 0.17 | K47: 24.1 | L47: 29.2 | M47: 20.6 | N47: 17.6 | O47: 3.08
A49: 3.) Stock Price Stability
C50: The stock's beta is 1.2675 which means the stock is about 26% more volatile than the broader market.
A52: 4.) Growth in Revenue and Earnings | C52: The stock has show high profit (20.6%) and sales growth (24.1%) better than most of its peers.
A54: 5.) Environmental and Social Initiatives
C55: 1. Regulatory Compliance and Risk Mitigation By adopting sustainable practices like zero liquid discharge (ZLD), renewable energy use, and proper waste management, the company ensures compliance with environmental regulations. Avoiding penalties or legal issues fosters operational continuity and strengthens its reputation with regulators and stakeholders. 2. Cost Efficiency Through Sustainable Practices Investments in renewable energy (e.g., solar power) and water recycling reduce long-term operating costs. Efficient resource utilization minimizes waste, turning potential liabilities into value-adding processes. 3. Enhanced Brand Reputation Commitment to sustainability and social responsibility attracts investors, customers, and partners who prioritize ethical and eco-friendly practices. A strong ESG (Environmental, Social, and Governance) profile can lead to inclusion in sustainability indexes, further improving investor confidence. 4. Customer and Market Advantage Many global customers, particularly in the specialty chemicals industry, prefer suppliers with strong environmental credentials. Compliance with international sustainability standards enhances export opportunities and helps attract clients who are aligning with ESG goals. 5. Employee Retention and Productivity Initiatives like workplace safety programs, skill development, and community engagement improve employee satisfaction and loyalty. A motivated and skilled workforce contributes to long-term operational excellence. 6. Future-Proofing Against Market Trends Global industries are increasingly moving toward green chemistry and sustainable products. Anupam Rasayan's focus on sustainability positions it well to adapt to market changes and regulations. Its commitment to eco-friendly manufacturing gives it a competitive edge as customers and governments demand greener solutions.
